<robot name="monoped">

    <link name="world">
    </link>
    
    <link name="contactsensor_link">
 	    <inertial >
            <origin xyz="0 0 0" rpy="0 0 0"/>
            <mass value="0.01" />
            <inertia ixx="1.28e-06" ixy="0.0" ixz="0.0" iyy="1.28e-06" iyz="0.0" izz="1.28e-06"/>
        </inertial>
        <collision>
            <origin xyz="0 0 0" rpy="0 0 0"/>
            <geometry>
                <sphere radius="0.030"/>
            </geometry>
        </collision>
        <visual>
            <origin rpy="0.0 0 0" xyz="0 0 0"/>
            <geometry>
                <sphere radius="0.030"/>
            </geometry>
        </visual>
	</link>
	
	<link name="lowerleg">
        <inertial>
            <origin xyz="0 0 0" rpy="0 0 0"/>
            <mass value="0.0292" />
            <inertia ixx="8.7076833333e-06" ixy="0.0" ixz="0.0" iyy="0.000370889177667" iyz="0.0" izz="0.000363771677667"/>
        </inertial>
        <collision>
            <origin rpy="0.0 0.0 0.0" xyz="0.0 0.0 0.0"/>
	      <geometry>
	        <mesh filename="package://legged_robots_description/meshes/leg/lowerleg.dae" scale="1 1 1"/>
	      </geometry>
        </collision>
	    <visual>
	      <geometry>
	        <mesh filename="package://legged_robots_description/meshes/leg/lowerleg.dae" scale="1 1 1"/>
	      </geometry>
	    </visual>
    </link>
    
    
    <link name="upperleg">
        <inertial>
            <origin xyz="-0.175 0 0" rpy="0 0 0"/>
            <mass value="0.1168" />
            <inertia ixx="0.000119502849333" ixy="0.0" ixz="0.0" iyy="0.00158478921733" iyz="0.0" izz="0.00158585686667"/>
        </inertial>
        <collision>
            <origin rpy="0.0 0.0 0.0" xyz="-0.35 0.0 0.0"/>
	      <geometry>
	        <mesh filename="package://legged_robots_description/meshes/leg/upperleg.dae" scale="1 1 1"/>
	      </geometry>
        </collision>
	    <visual>
	      <origin rpy="0.0 0.0 0.0" xyz="-0.35 0.0 0.0"/>
	      <geometry>
	        <mesh filename="package://legged_robots_description/meshes/leg/upperleg.dae" scale="1 1 1"/>
	      </geometry>
	    </visual>
    </link>
    
    <link name="hipassembly">
        <inertial>
            <origin xyz="-0.08125 0 0" rpy="0 0 0"/>
            <mass value="0.1168" />
            <inertia ixx="0.00140906974933" ixy="0.0" ixz="0.0" iyy="0.001529597616" iyz="0.0" izz="0.000218659333333"/>
        </inertial>
        <collision>
            <origin rpy="0.0 0.0 0.0" xyz="-0.08125 0.0 0.0"/>
	      <geometry>
	        <mesh filename="package://legged_robots_description/meshes/leg/hipassembly.dae" scale="1 1 1"/>
	      </geometry>
        </collision>
	    <visual>
	      <origin rpy="0.0 0.0 0.0" xyz="-0.08125 0.0 0.0"/>
	      <geometry>
	        <mesh filename="package://legged_robots_description/meshes/leg/hipassembly.dae" scale="1 1 1"/>
	      </geometry>
	    </visual>
    </link>
    
    <link name="base">
        <inertial>
            <origin xyz="-0.23 0 0" rpy="0 0 0"/>
            <mass value="0.4672" />
            <inertia ixx="0.00293333333333" ixy="0.0" ixz="0.0" iyy="0.00506133333333" iyz="0.0" izz="0.00506133333333"/>
        </inertial>
        <collision>
            <origin xyz="-0.23 0 0" rpy="0 0 0"/>
            <geometry>
                <box size="0.30 0.20 0.20"/>
            </geometry>
        </collision>
	    <visual>
            <origin xyz="-0.23 0 0" rpy="0 0 0"/>
	      <geometry>
	        <box size="0.30 0.20 0.20"/>
	      </geometry>
	      <material name="blue">
	        <color rgba="0 0 1.0 1.0"/>
	      </material>
	    </visual>
    </link>
	
	
    <joint name="contactsensor_world_link_joint" type="revolute">
        <parent link="world"/>
        <child link="contactsensor_link"/>
        <origin xyz="0 0 0.03" rpy="0.0 1.57 0"/>
        <limit effort="20" lower="-1.57" upper="1.57" velocity="12.0"/>
        <axis xyz="0 0 1"/>
    </joint>
    
    <joint name="lowerleg_contactsensor_link_joint" type="fixed">
        <parent link="contactsensor_link"/>
        <child link="lowerleg"/>
        <origin xyz="-0.35 0 0" rpy="0 0 0"/>
    </joint>
    
    
    <joint name="kfe_joint" type="revolute">
        <origin xyz="0.0 0.00000 0.00000" rpy="0.0 0.0 0.0"/>
        <parent link="lowerleg"/>
        <child  link="upperleg"/>
        <limit effort="20" lower="0.0" upper="1.6" velocity="12.0"/>
        <axis xyz="0 0 1"/>
    </joint>
    
    <joint name="hfe_joint" type="revolute">
        <origin xyz="-0.35000 0.00000 0.00000" rpy="-1.5707963705062866 0.0 0.0"/>
        <parent link="upperleg"/>
        <child  link="hipassembly"/>
        <limit effort="20" lower="-1.6" upper="1.6" velocity="12.0"/>
        <axis xyz="0 1 0"/>
    </joint>
    
    <joint name="haa_joint" type="revolute">
        <origin xyz="0.0 0.0 0" rpy="0 0 0"/>
        <parent link="hipassembly"/>
        <child  link="base"/>
        <!--<limit effort="20" lower="-1.6" upper="1.6" velocity="12.0"/>-->
        <limit effort="20" lower="0.0" upper="0.0" velocity="12.0"/>
        <axis xyz="0 0 1"/>
    </joint>
    

    
    <!-- Contact Sensor -->
    <gazebo reference="contactsensor_link">
        <material>Gazebo/Blue</material>
        <kp>1000.0</kp>
        <kd>1000.0</kd>
        <mu1>1000000.0</mu1>
        <mu2>1000000.0</mu2>

    </gazebo>
    
    <gazebo reference="lowerleg">
        <kp>1000.0</kp>
        <kd>1000.0</kd>
        <mu1>0.5</mu1>
        <mu2>0.5</mu2>
    </gazebo>
    
    
    <gazebo reference="upperleg">
        <kp>1000.0</kp>
        <kd>1000.0</kd>
        <mu1>0.5</mu1>
        <mu2>0.5</mu2>
    </gazebo>
    
    <gazebo reference="hipassembly">
        <kp>1000.0</kp>
        <kd>1000.0</kd>
        <mu1>0.5</mu1>
        <mu2>0.5</mu2>
    </gazebo>
    
    <gazebo reference="base">
        <kp>1000.0</kp>
        <kd>1000.0</kd>
        <mu1>0.5</mu1>
        <mu2>0.5</mu2>
        <material>Gazebo/Green</material>
    </gazebo>
    
    <!-- Sensors -->
    
    
    <gazebo>
        <plugin name="gazebo_ros_control" filename="libgazebo_ros_control.so">
            <robotNamespace>/monoped</robotNamespace>
        </plugin>
    </gazebo>

    <gazebo>
        <plugin name="p3d_base_controller" filename="libgazebo_ros_p3d.so">
            <alwaysOn>true</alwaysOn>
            <!--<updateRate>50.0</updateRate>-->
            <bodyName>base</bodyName>
            <topicName>odom</topicName>
            <gaussianNoise>0.01</gaussianNoise>
            <frameName>world</frameName>
            <xyzOffsets>0 0 0</xyzOffsets>
            <rpyOffsets>0 0 0</rpyOffsets>
        </plugin>
    </gazebo>
    
    <!-- IMU sensor -->
    <gazebo>
        <plugin name="gazebo_ros_imu_controller" filename="libgazebo_ros_imu.so">
          <robotNamespace>/monoped</robotNamespace>
          <topicName>imu/data</topicName>
          <serviceName>imu/service</serviceName>
          <bodyName>base</bodyName>
          <gaussianNoise>0</gaussianNoise>
          <rpyOffsets>0 0 0</rpyOffsets>
          <!--<updateRate>50.0</updateRate>-->
          <alwaysOn>true</alwaysOn>
          <gaussianNoise>0</gaussianNoise>
        </plugin>
    </gazebo>
    
    
    
    <transmission name="haa_joint_trans">
      <type>transmission_interface/SimpleTransmission</type>
      <joint name="haa_joint">
        <hardwareInterface>hardware_interface/EffortJointInterface</hardwareInterface>
      </joint>
      <actuator name="haa_jointMotor">
        <hardwareInterface>hardware_interface/EffortJointInterface</hardwareInterface>
        <mechanicalReduction>1</mechanicalReduction>
      </actuator>
    </transmission>

    <transmission name="hfe_joint_trans">
      <type>transmission_interface/SimpleTransmission</type>
      <joint name="hfe_joint">
        <hardwareInterface>hardware_interface/EffortJointInterface</hardwareInterface>
      </joint>
      <actuator name="hfe_jointMotor">
        <hardwareInterface>hardware_interface/EffortJointInterface</hardwareInterface>
        <mechanicalReduction>1</mechanicalReduction>
      </actuator>
    </transmission>

    <transmission name="kfe_joint_trans">
      <type>transmission_interface/SimpleTransmission</type>
      <joint name="kfe_joint">
        <hardwareInterface>hardware_interface/EffortJointInterface</hardwareInterface>
      </joint>
      <actuator name="kfe_jointMotor">
        <hardwareInterface>hardware_interface/EffortJointInterface</hardwareInterface>
        <mechanicalReduction>1</mechanicalReduction>
      </actuator>
    </transmission>
    

</robot>

